Workbook

Sheet Gap
B2: IPoM Mar.26 | C2: IPoM Abr (f)
A3: 21 | B3: -0.47669451 | C3: -0.477
B4: -0.69615981 | C4: -0.696
B5: 3.3627222 | C5: 3.363 | F5: GRÁFICO I
B6: 4.1499363 | C6: 4.15 | F6: BRECHA DE ACTIVIDAD (1) (2)
A7: 22 | B7: 3.0890234 | C7: 3.089 | F7: (nivel, puntos porcentuales)
B8: 2.2600518 | C8: 2.26
B9: 1.8192648 | C9: 1.819
B10: -0.16586608 | C10: -0.166
A11: 23 | B11: 0.86446165 | C11: 0.864
B12: 0.030521673 | C12: 0.031
B13: -0.15273533 | C13: -0.153
B14: -0.20572747 | C14: -0.206
A15: 24 | B15: 0.34104505 | C15: 0.341
B16: -0.90931071 | C16: -0.909
B17: -0.44498129 | C17: -0.445
B18: -0.14050141 | C18: -0.141
A19: 25 | B19: 0.69031174 | C19: 0.69
B20: -0.072477643 | C20: -0.072
B21: -0.26531175 | C21: -0.265
B22: -0.2966665 | C22: -0.297
A23: 26 | B23: -0.38531516 | C23: -0.5
B24: -0.36051391 | C24: -0.5
B25: -0.43901266 | C25: -0.48362563
B26: -0.49813742 | C26: -0.54155869
A27: 27 | B27: -0.51635165 | C27: -0.60946444
B28: -0.48235892 | C28: -0.53812929
B29: -0.42452285 | C29: -0.45395934
B30: -0.37299685 | C30: -0.39215237
A31: 28 | B31: -0.30020776 | C31: -0.37200515

Sheet IPC
B1: IPC (a/a, %) | C1: -90 | D1: -70 | E1: -10 | F1: 10 | G1: 70 | H1: 90 | I1: IPC (a/a, %) | J1: IPoM Abr (IRIS maneja diff en logs) | K1: IPoM Abr (f)
A2: 21 | B2: 2.9471598 | C2: 2.9471598 | D2: 0 | E2: 0 | F2: 0 | G2: 0 | H2: 0 | I2: 2.9471598 | J2: 2.9045659 | K2: =100*(EXP(('Base completa_fcast_alt'!E15-'Base completa_fcast_alt'!E11)/100) - 1) -> 2.9471599 | M2: GRÁFICO II
B3: 3.5896625 | C3: 3.5896625 | D3: 0 | E3: 0 | F3: 0 | G3: 0 | H3: 0 | I3: 3.5896625 | J3: 3.5267356 | K3: =100*(EXP(('Base completa_fcast_alt'!E16-'Base completa_fcast_alt'!E12)/100) - 1) -> 3.5896629 | M3: PROYECCIONES DE CRECIMIENTO E INFLACIÓN (1)
B4: 4.8867842 | C4: 4.8867842 | D4: 0 | E4: 0 | F4: 0 | G4: 0 | H4: 0 | I4: 4.8867842 | J4: 4.7711337 | K4: =100*(EXP(('Base completa_fcast_alt'!E17-'Base completa_fcast_alt'!E13)/100) - 1) -> 4.8867845 | M4: (variación anual, porcentaje)
B5: 6.633641 | C5: 6.633641 | D5: 0 | E5: 0 | F5: 0 | G5: 0 | H5: 0 | I5: 6.633641 | J5: 6.4228857 | K5: =100*(EXP(('Base completa_fcast_alt'!E18-'Base completa_fcast_alt'!E14)/100) - 1) -> 6.6336413
A6: 22 | B6: 8.3096348 | C6: 8.3096348 | D6: 0 | E6: 0 | F6: 0 | G6: 0 | H6: 0 | I6: 8.3096348 | J6: 7.9823928 | K6: =100*(EXP(('Base completa_fcast_alt'!E19-'Base completa_fcast_alt'!E15)/100) - 1) -> 8.309635
B7: 11.519064 | C7: 11.519064 | D7: 0 | E7: 0 | F7: 0 | G7: 0 | H7: 0 | I7: 11.519064 | J7: 10.902537 | K7: =100*(EXP(('Base completa_fcast_alt'!E20-'Base completa_fcast_alt'!E16)/100) - 1) -> 11.519063
B8: 13.64786 | C8: 13.64786 | D8: 0 | E8: 0 | F8: 0 | G8: 0 | H8: 0 | I8: 13.64786 | J8: 12.793453 | K8: =100*(EXP(('Base completa_fcast_alt'!E21-'Base completa_fcast_alt'!E17)/100) - 1) -> 13.64786
B9: 12.976356 | C9: 12.976356 | D9: 0 | E9: 0 | F9: 0 | G9: 0 | H9: 0 | I9: 12.976356 | J9: 12.200838 | K9: =100*(EXP(('Base completa_fcast_alt'!E22-'Base completa_fcast_alt'!E18)/100) - 1) -> 12.976356
A10: 23 | B10: 11.901672 | C10: 11.901672 | D10: 0 | E10: 0 | F10: 0 | G10: 0 | H10: 0 | I10: 11.901672 | J10: 11.245037 | K10: =100*(EXP(('Base completa_fcast_alt'!E23-'Base completa_fcast_alt'!E19)/100) - 1) -> 11.901672
B11: 8.6905467 | C11: 8.6905467 | D11: 0 | E11: 0 | F11: 0 | G11: 0 | H11: 0 | I11: 8.6905467 | J11: 8.3334638 | K11: =100*(EXP(('Base completa_fcast_alt'!E24-'Base completa_fcast_alt'!E20)/100) - 1) -> 8.690547
B12: 5.2226591 | C12: 5.2226591 | D12: 0 | E12: 0 | F12: 0 | G12: 0 | H12: 0 | I12: 5.2226591 | J12: 5.0908482 | K12: =100*(EXP(('Base completa_fcast_alt'!E25-'Base completa_fcast_alt'!E21)/100) - 1) -> 5.2226589
B13: 4.0125268 | C13: 4.0125268 | D13: 0 | E13: 0 | F13: 0 | G13: 0 | H13: 0 | I13: 4.0125268 | J13: 3.9341156 | K13: =100*(EXP(('Base completa_fcast_alt'!E26-'Base completa_fcast_alt'!E22)/100) - 1) -> 4.0125272
A14: 24 | B14: 3.3366953 | C14: 3.3366953 | D14: 0 | E14: 0 | F14: 0 | G14: 0 | H14: 0 | I14: 3.3366953 | J14: 3.2822358 | K14: =100*(EXP(('Base completa_fcast_alt'!E27-'Base completa_fcast_alt'!E23)/100) - 1) -> 3.3366956
B15: 3.5604967 | C15: 3.5604967 | D15: 0 | E15: 0 | F15: 0 | G15: 0 | H15: 0 | I15: 3.5604967 | J15: 3.4985765 | K15: =100*(EXP(('Base completa_fcast_alt'!E28-'Base completa_fcast_alt'!E24)/100) - 1) -> 3.5604972
B16: 4.3225958 | C16: 4.3225958 | D16: 0 | E16: 0 | F16: 0 | G16: 0 | H16: 0 | I16: 4.3225958 | J16: 4.2317795 | K16: =100*(EXP(('Base completa_fcast_alt'!E29-'Base completa_fcast_alt'!E25)/100) - 1) -> 4.3225963
B17: 4.4692436 | C17: 4.4692436 | D17: 0 | E17: 0 | F17: 0 | G17: 0 | H17: 0 | I17: 4.4692436 | J17: 4.3722522 | K17: =100*(EXP(('Base completa_fcast_alt'!E30-'Base completa_fcast_alt'!E26)/100) - 1) -> 4.4692433
A18: 25 | B18: 4.8487588 | C18: 4.8487588 | D18: 0 | E18: 0 | F18: 0 | G18: 0 | H18: 0 | I18: 4.8487588 | J18: 4.7348733 | K18: =100*(EXP(('Base completa_fcast_alt'!E31-'Base completa_fcast_alt'!E27)/100) - 1) -> 4.8487584
B19: 4.360004 | C19: 4.360004 | D19: 0 | E19: 0 | F19: 0 | G19: 0 | H19: 0 | I19: 4.360004 | J19: 4.2676313 | K19: =100*(EXP(('Base completa_fcast_alt'!E32-'Base completa_fcast_alt'!E28)/100) - 1) -> 4.3600037
B20: 4.2298464 | C20: 4.2298464 | D20: 0 | E20: 0 | F20: 0 | G20: 0 | H20: 0 | I20: 4.2298464 | J20: 4.1428336 | K20: =100*(EXP(('Base completa_fcast_alt'!E33-'Base completa_fcast_alt'!E29)/100) - 1) -> 4.2298458
B21: 3.4447696 | C21: 3.4447696 | D21: 0 | E21: 0 | F21: 0 | G21: 0 | H21: 0 | I21: 3.4447696 | J21: 3.3867657 | K21: =100*(EXP(('Base completa_fcast_alt'!E34-'Base completa_fcast_alt'!E30)/100) - 1) -> 3.4447699
A22: 26 | C22: 2.5243253 | D22: 0.024387382 | E22: 0.036506587 | F22: 0.010073798 | G22: 0.036506587 | H22: 0.024387382 | I22: 2.5902561 | J22: 2.6263086 | K22: =100*(EXP(('Base completa_fcast_alt'!E35-'Base completa_fcast_alt'!E31)/100) - 1) -> 2.6611004 | M22: PROYECCIONES DE INFLACIÓN SV (1)
C23: 3.5505763 | D23: 0.15763962 | E23: 0.23597794 | F23: 0.065116857 | G23: 0.23597794 | H23: 0.15763962 | I23: 3.9767523 | J23: 4.0317624 | K23: =100*(EXP(('Base completa_fcast_alt'!E36-'Base completa_fcast_alt'!E32)/100) - 1) -> 4.1141409 | M23: (variación anual, porcentaje)
C24: 2.8822053 | D24: 0.38399359 | E24: 0.57481754 | F24: 0.15861784 | G24: 0.57481754 | H24: 0.38399359 | I24: 3.9203254 | J24: 4.1872919 | K24: =100*(EXP(('Base completa_fcast_alt'!E37-'Base completa_fcast_alt'!E33)/100) - 1) -> 4.2761956
C25: 2.6122181 | D25: 0.5290743 | E25: 0.79199549 | F25: 0.21854694 | G25: 0.79199549 | H25: 0.5290743 | I25: 4.0425613 | J25: 4.2649118 | K25: =100*(EXP(('Base completa_fcast_alt'!E38-'Base completa_fcast_alt'!E34)/100) - 1) -> 4.3571662
A26: 27 | C26: 2.3181171 | D26: 0.61979623 | E26: 0.92780128 | F26: 0.25602182 | G26: 0.92780128 | H26: 0.61979623 | I26: 3.9937255 | J26: 3.9829624 | K26: =100*(EXP(('Base completa_fcast_alt'!E39-'Base completa_fcast_alt'!E35)/100) - 1) -> 4.0633456
C27: 0.90829738 | D27: 0.68089074 | E27: 1.0192565 | F27: 0.28125839 | G27: 1.0192565 | H27: 0.68089074 | I27: 2.7490738 | J27: 2.7990185 | K27: =100*(EXP(('Base completa_fcast_alt'!E40-'Base completa_fcast_alt'!E36)/100) - 1) -> 2.8385596
C28: 0.65576082 | D28: 0.70505879 | E28: 1.0554347 | F28: 0.29124159 | G28: 1.0554347 | H28: 0.70505879 | I28: 2.5618751 | J28: 2.4133396 | K28: =100*(EXP(('Base completa_fcast_alt'!E41-'Base completa_fcast_alt'!E37)/100) - 1) -> 2.4426957
C29: 0.88341708 | D29: 0.70970728 | E29: 1.0623932 | F29: 0.29316176 | G29: 1.0623932 | H29: 0.70970728 | I29: 2.8020985 | J29: 2.716681 | K29: =100*(EXP(('Base completa_fcast_alt'!E42-'Base completa_fcast_alt'!E38)/100) - 1) -> 2.7539192
A30: 28 | C30: 1.0034487 | D30: 0.73862892 | E30: 1.1056874 | F30: 0.30510854 | G30: 1.1056874 | H30: 0.73862892 | I30: 3.0003193 | J30: 2.9505665 | K30: =100*(EXP(('Base completa_fcast_alt'!E43-'Base completa_fcast_alt'!E39)/100) - 1) -> 2.9945275
B32: IPC SV (a/a,%) | C32: -90 | D32: -70 | E32: -10 | F32: 10 | G32: 70 | H32: 90 | I32: IPC SV (a/a,%) | J32: IPoM Abr (IRIS maneja diff en logs) | K32: IPoM Abr (f)
A33: 21 | B33: 3.1831676 | C33: 3.1831676 | D33: 0 | E33: 0 | F33: 0 | G33: 0 | H33: 0 | I33: 3.1831676 | J33: 3.1335549 | K33: =100*(EXP(('Base completa_fcast_alt'!F15-'Base completa_fcast_alt'!F11)/100) - 1) -> 3.1831677
B34: 3.2308466 | C34: 3.2308466 | D34: 0 | E34: 0 | F34: 0 | G34: 0 | H34: 0 | I34: 3.2308466 | J34: 3.1797524 | K34: =100*(EXP(('Base completa_fcast_alt'!F16-'Base completa_fcast_alt'!F12)/100) - 1) -> 3.2308462
B35: 3.9227893 | C35: 3.9227893 | D35: 0 | E35: 0 | F35: 0 | G35: 0 | H35: 0 | I35: 3.9227893 | J35: 3.8478027 | K35: =100*(EXP(('Base completa_fcast_alt'!F17-'Base completa_fcast_alt'!F13)/100) - 1) -> 3.9227886
B36: 4.7234973 | C36: 4.7234973 | D36: 0 | E36: 0 | F36: 0 | G36: 0 | H36: 0 | I36: 4.7234973 | J36: 4.6153331 | K36: =100*(EXP(('Base completa_fcast_alt'!F18-'Base completa_fcast_alt'!F14)/100) - 1) -> 4.7234971
A37: 22 | B37: 6.6464465 | C37: 6.6464465 | D37: 0 | E37: 0 | F37: 0 | G37: 0 | H37: 0 | I37: 6.6464465 | J37: 6.4348939 | K37: =100*(EXP(('Base completa_fcast_alt'!F19-'Base completa_fcast_alt'!F15)/100) - 1) -> 6.6464466
B38: 8.8588638 | C38: 8.8588638 | D38: 0 | E38: 0 | F38: 0 | G38: 0 | H38: 0 | I38: 8.8588638 | J38: 8.4882029 | K38: =100*(EXP(('Base completa_fcast_alt'!F20-'Base completa_fcast_alt'!F16)/100) - 1) -> 8.8588638
B39: 10.308272 | C39: 10.308272 | D39: 0 | E39: 0 | F39: 0 | G39: 0 | H39: 0 | I39: 10.308272 | J39: 9.810873 | K39: =100*(EXP(('Base completa_fcast_alt'!F21-'Base completa_fcast_alt'!F17)/100) - 1) -> 10.308272
B40: 10.313103 | C40: 10.313103 | D40: 0 | E40: 0 | F40: 0 | G40: 0 | H40: 0 | I40: 10.313103 | J40: 9.8152528 | K40: =100*(EXP(('Base completa_fcast_alt'!F22-'Base completa_fcast_alt'!F18)/100) - 1) -> 10.313103
A41: 23 | B41: 9.9620399 | C41: 9.9620399 | D41: 0 | E41: 0 | F41: 0 | G41: 0 | H41: 0 | I41: 9.9620399 | J41: 9.4965029 | K41: =100*(EXP(('Base completa_fcast_alt'!F23-'Base completa_fcast_alt'!F19)/100) - 1) -> 9.9620401
...

Sheet TPM
B1: IPoM Mar.26 | C1: IPoM Abr (f)
A2: 21 | B2: 0.5 | C2: 0.5
B3: 0.5 | C3: 0.5 | E3: GRÁFICO III
B4: 0.95703125 | C4: 0.96 | E4: TPM
B5: 2.8306452 | C5: 2.82 | E5: (nivel, puntos porcentuales)
A6: 22 | B6: 5.125 | C6: 5.1133333
B7: 7.9475806 | C7: 7.9433333
B8: 9.8968254 | C8: 9.91
B9: 11.192623 | C9: 11.19
A10: 23 | B10: 11.25 | C10: 11.25
B11: 11.25 | C11: 11.25
B12: 10.379032 | C12: 10.356667
B13: 9.0625 | C13: 9.0566667
A14: 24 | B14: 7.5992063 | C14: 7.5833333
B15: 6.2943548 | C15: 6.28
B16: 5.6844262 | C16: 5.6766667
B17: 5.2701613 | C17: 5.2666667
A18: 25 | B18: 5 | C18: 5
B19: 5 | C19: 5
B20: 4.8306452 | C20: 4.8266667
B21: 4.7137097 | C21: 4.7133333
A22: 26 | B22: 4.5 | C22: 4.4941601
B23: 4.53 | C23: 4.5235813
B24: 4.75 | C24: 4.7492865
B25: 4.56 | C25: 4.581584
A26: 27 | B26: 4.32 | C26: 4.324754
B27: 4.25 | C27: 4.2280095
B28: 4.25 | C28: 4.2395048
B29: 4.25 | C29: 4.2405463
A30: 28 | B30: 4.25 | C30: 4.2107615

Sheet MateriaPrima
A1: Cobre | E1: Petróleo
A3: Año | B3: IPoM Mar.26 | C3: IPoM Abr (f) | E3: Año | F3: IPoM Mar.26 | G3: IPoM Abr (f)
A4: 21 | B4: 3.8458572 | C4: 3.8458572 | E4: 21 | F4: 57.79 | G4: 57.79
B5: 4.4047219 | C5: 4.4047219 | F5: 66.09 | G5: 66.090001
B6: 4.2509374 | C6: 4.2509374 | F6: 70.623333 | G6: 70.623334
B7: 4.3990278 | C7: 4.3990278 | F7: 77.446667 | G7: 77.446667
A8: 22 | B8: 4.5291451 | C8: 4.5291451 | E8: 22 | F8: 94.453333 | G8: 94.453334
B9: 4.321127 | C9: 4.321127 | F9: 108.72333 | G9: 108.72333
B10: 3.511668 | C10: 3.511668 | F10: 93.183333 | G10: 93.183333
B11: 3.6315567 | C11: 3.6315567 | F11: 82.786667 | G11: 82.786667
A12: 23 | B12: 4.0507288 | C12: 4.0507288 | E12: 23 | F12: 76.076667 | G12: 76.076667
B13: 3.8456727 | C13: 3.8456727 | F13: 73.76 | G13: 73.76
B14: 3.7902401 | C14: 3.7902401 | F14: 82.296667 | G14: 82.296667
B15: 3.705543 | C15: 3.705543 | F15: 78.41 | G15: 78.409999
A16: 24 | B16: 3.8299722 | C16: 3.8299722 | E16: 24 | F16: 77.56 | G16: 77.56
B17: 4.4230397 | C17: 4.4230397 | F17: 81.713333 | G17: 81.713333
B18: 4.1748737 | C18: 4.1748737 | F18: 76.24 | G18: 76.24
B19: 4.1630092 | C19: 4.1630092 | F19: 70.686667 | G19: 70.686667
A20: 25 | B20: 4.2392627 | C20: 4.2392627 | E20: 25 | F20: 71.836667 | G20: 71.836667
B21: 4.3175468 | C21: 4.3175468 | F21: 64.626667 | G21: 64.626666
B22: 4.4417027 | C22: 4.4417027 | F22: 65.736667 | G22: 65.736666
B23: 5.0349705 | C23: 5.0349705 | F23: 59.64 | G23: 59.64
A24: 26 | B24: 5.2098 | C24: 5.2098 | E24: 26 | F24: 82.5 | G24: 83.150443
B25: 5.4386 | C25: 5.4386 | F25: 88.6 | G25: 100
B26: 5.5144 | C26: 5.5144 | F26: 87.5 | G26: 100
B27: 5.4373 | C27: 5.4373 | F27: 85.6 | G27: 90
A28: 27 | B28: 5.1871 | C28: 5.1871 | E28: 27 | F28: 78 | G28: 85
B29: 5.1124 | C29: 5.1124 | F29: 75.2 | G29: 85
B30: 5.0627 | C30: 5.0627 | F30: 73.3 | G30: 85
B31: 5.0378 | C31: 5.0378 | F31: 72.4 | G31: 85

Sheet Base completa_fcast_alt
A1: Variables -> | B1: L_GDP | C1: L_GDP_BAR | D1: L_GDP_GAP | E1: L_CPI | F1: L_CPIXFE | G1: TPM | H1: TPMN1 | I1: T_COLOC | J1: L_Z | K1: CRECSC | L1: L_PCU | M1: L_WTI | N1: FFR | O1: UST10 | P1: VIX | Q1: L_Z_GAP | R1: L_Food | S1: PCU_NOM | T1: WTI_NOM | U1: L_PCU_NOM | V1: L_WTI_NOM | W1: CPI_US | X1: CPI_US_2020 | Y1: L_CPI_US | Z1: D4L_CPI_US | AA1: DLA_CPI_US | AB1: DLA_GDP | AC1: D4L_GDP | AD1: DLA_GDP_BAR | AE1: D4L_GDP_BAR | AF1: DLA_GDP_GAP | AG1: D4L_GDP_GAP | AH1: DLA_CPI | AI1: D4L_CPI | AJ1: DLA_CPIXFE | AK1: D4L_CPIXFE | AL1: DLA_Z | AM1: D4L_Z | AN1: DLA_PCU | AO1: D4L_PCU | AP1: DLA_WTI | AQ1: D4L_WTI | AR1: DLA_Z_GAP | AS1: D4L_Z_GAP | AT1: DLA_Food | AU1: D4L_Food | AV1: DLA_PCU_NOM | AW1: D4L_PCU_NOM | AX1: DLA_WTI_NOM | AY1: D4L_WTI_NOM | AZ1: DLA_CPIRES | BA1: L_Z_INDEX | BB1: D4L_CPI_GAP_XFE
A2: Comments -> | B2: Real GDP (100*log) | C2: Trend in Real GDP (100*log) | D2: Output Gap (in %) | E2: CPI (level, 100*log) | F2: Core CPI (level, 100*log) | G2: Nominal Policy Interest Rate (in % pa) | H2: Neutral Interest Rate (in % pa) | I2: Tasa de interes de las colocaciones en UF (%) | J2: Real Exchange Rate (level, 100*log) | K2: Foreign Output growth (in %) | L2: Copper Price (USD per lb, 100*log) | M2: Oil Price (WTI, USD per barreÃ±, 100*log) | N2: Federal Fund Rate (%) | O2: T-Bill 10 years (%) | P2: VIX (index) | Q2: Real Exchange Rate Gap (in %) | R2: YoY Inflation Food (in %) | AB2: Quarterly Growth in Real GDP(in % pa) | AC2: Real GDP Growth YoY (in %) | AD2: Real GDP Trend Growth QoQ @ar (in %) | AH2: QoQ Inflation (in % @ar) | AI2: YoY Inflation (in %) | AJ2: QoQ Core Inflation (in % @ar) | AK2: YoY Core Inflation (in %) | AZ2: QoQ Residual Inflation (in % @ar) | BA2: Real Exchange Rate (level, 100*log)
A3: 2018Q1 | B3: 1066.0937 | C3: 1065.9841 | D3: 0.10959829 | E3: 431.87085 | F3: 435.00831 | G3: 2.5 | H3: 3.9209467 | I3: 3.4933333 | J3: 448.32912 | K3: 3.9488793 | L3: 118.69108 | M3: 417.87141 | N3: 1.4466667 | O3: 2.76 | P3: 17.354754 | Q3: -12.187895 | R3: 0.41077653 | S3: 3.1567117 | T3: 62.886667 | U3: 3.1567117 | V3: 62.886666 | W3: 249.32167 | X3: 96.331008 | Y3: 551.87439 | Z3: 2.2237092 | AA3: 3.3564452 | AB3: 3.5287183 | AC3: 3.9850121 | AD3: 2.5667818 | AE3: 2.566771 | AF3: 0.96193651 | AG3: 1.4182411 | AH3: 2.8897269 | AI3: 2.0142434 | AJ3: 2.5161583 | AK3: 2.137086 | AL3: -10.754186 | AM3: -3.1836039 | AN3: 5.4326396 | AO3: 15.422272 | AP3: 47.586129 | AQ3: 17.235063 | AR3: -10.754186 | AS3: -3.1836039 | AT3: -7.8423974 | AU3: -11.821606 | AV3: 8.7890848 | AW3: 17.645982 | AX3: 50.942575 | AY3: 19.458772 | AZ3: 0.37356864 | BA3: 88.525553 | BB3: -0.12284268
A4: 2018Q2 | B4: 1067.8513 | C4: 1066.5525 | D4: 1.2987746 | E4: 432.50929 | F4: 435.87698 | G4: 2.5 | H4: 3.8900043 | I4: 3.31 | J4: 449.66341 | K4: 3.8914968 | L4: 116.8816 | M4: 425.19484 | N4: 1.7366667 | O4: 2.92 | P4: 15.3375 | Q4: -10.853613 | R4: 1.2331865 | S4: 3.1169827 | T4: 68.033333 | U4: 3.1169827 | V4: 68.033333 | W4: 250.679 | X4: 96.855444 | Y4: 552.41732 | Z4: 2.6513329 | AA4: 2.1717358 | AB4: 7.0306419 | AC4: 4.8169368 | AD4: 2.2739365 | AE4: 2.4935678 | AF4: 4.7567055 | AG4: 2.323369 | AH4: 2.5537525 | AI4: 2.1253632 | AJ4: 3.4747113 | AK4: 1.9579435 | AL4: 5.3371265 | AM4: -3.9478049 | AN4: -7.2379159 | AO4: 16.696501 | AP4: 29.293711 | AQ4: 31.72959 | AR4: 5.3371265 | AS4: -3.9478049 | AT4: 3.2896398 | AU4: -4.6884776 | AV4: -5.0661801 | AW4: 19.347834 | AX4: 31.465447 | AY4: 34.380923 | AZ4: -0.92095883 | BA4: 89.714648 | BB4: 0.16741971
A5: 2018Q3 | B5: 1067.1976 | C5: 1067.121 | D5: 0.076530427 | E5: 433.10459 | F5: 436.20286 | G5: 2.5 | H5: 3.8534229 | I5: 3.19 | J5: 452.20253 | K5: 3.7146055 | L5: 104.61172 | M5: 427.29532 | N5: 1.9233333 | O5: 2.9266667 | P5: 12.856825 | Q5: -8.3144901 | R5: -4.8244849 | S5: 2.7681439 | T5: 69.756667 | U5: 2.7681439 | V5: 69.756667 | W5: 251.68633 | X5: 97.24465 | Y5: 552.81836 | Z5: 2.575465 | AA5: 1.6041468 | AB5: -2.614993 | AC5: 2.8753333 | AD5: 2.2739839 | AE5: 2.4203789 | AF5: -4.8889769 | AG5: 0.45495438 | AH5: 2.3812007 | AI5: 2.6138871 | AJ5: 1.3034836 | AK5: 2.0772056 | AL5: 10.156491 | AM5: -0.04965918 | AN5: -49.079517 | AO5: -6.4959712 | AP5: 8.401939 | AQ5: 34.466033 | AR5: 10.156491 | AS5: -0.04965918 | AT5: -24.230686 | AU5: -9.8146874 | AV5: -47.47537 | AW5: -3.9205062 | AX5: 10.006086 | AY5: 37.041498 | AZ5: 1.0777171 | BA5: 92.021779 | BB5: 0.53668149
A6: 2018Q4 | B6: 1068.4661 | C6: 1067.6895 | D6: 0.77658852 | E6: 433.54499 | F6: 436.52072 | G6: 2.7 | H6: 3.8132952 | I6: 3.0966667 | J6: 452.98448 | K6: 3.2817499 | L6: 105.26572 | M6: 410.27133 | N6: 2.22 | O6: 3.0333333 | P6: 21.053651 | Q6: -7.5325392 | R6: -5.9164802 | S6: 2.7976504 | T6: 59.076667 | U6: 2.7976504 | V6: 59.076667 | W6: 252.711 | X6: 97.640553 | Y6: 553.22465 | Z6: 2.189376 | AA6: 1.625176 | AB6: 5.0740977 | AC6: 3.2546162 | AD6: 2.2738653 | AE6: 2.3471419 | AF6: 2.8002324 | AG6: 0.90747436 | AH6: 1.7615993 | AI6: 2.3965698 | AJ6: 1.2714484 | AK6: 2.1414504 | AL6: 3.1278037 | AM6: 1.9668089 | AN6: 2.6159815 | AO6: -12.067203 | AP6: -68.09596 | AQ6: 4.2964548 | AR6: 3.1278037 | AS6: 1.9668089 | AT6: -4.3679814 | AU6: -8.2878561 | AV6: 4.2411575 | AW6: -9.877827 | AX6: -66.470784 | AY6: 6.4858307 | AZ6: 0.49015084 | BA6: 92.744165 | BB6: 0.25511943
A7: 2019Q1 | B7: 1068.6617 | C7: 1068.258 | D7: 0.40373298 | E7: 433.69337 | F7: 437.27562 | G7: 2.92 | H7: 3.7666602 | I7: 3.17 | J7: 452.24693 | K7: 3.1390783 | L7: 105.85014 | M7: 402.53878 | N7: 2.4033333 | O7: 2.6533333 | P7: 16.47 | Q7: -8.2700857 | R7: -4.6733255 | S7: 2.821561 | T7: 54.826667 | U7: 2.821561 | V7: 54.826667 | W7: 253.38567 | X7: 97.901225 | Y7: 553.49127 | Z7: 1.6168806 | AA7: 1.0664636 | AB7: 0.78252899 | AC7: 2.5680689 | AD7: 2.2739512 | AE7: 2.2739342 | AF7: -1.4914222 | AG7: 0.29413469 | AH7: 0.59353135 | AI7: 1.8225209 | AJ7: 3.0195909 | AK7: 2.2673086 | AL7: -2.950186 | AM7: 3.9178089 | AN7: 2.3376804 | AO7: -12.840943 | AP7: -30.9302 | AQ7: -15.332628 | AR7: -2.950186 | AS7: 3.9178089 | AT7: 4.9726191 | AU7: -5.084102 | AV7: 3.404144 | AW7: -11.224062 | AX7: -29.863737 | AY7: -13.715747 | AZ7: -2.4260595 | BA7: 92.062651 | BB7: -0.44478762
A8: 2019Q2 | B8: 1069.9984 | C8: 1068.8382 | D8: 1.1601073 | E8: 434.70264 | F8: 438.13934 | G8: 2.8766667 | H8: 3.7140251 | I8: 2.8933333 | J8: 453.44939 | K8: 3.0494439 | L8: 103.39172 | M8: 410.46177 | N8: 2.3966667 | O8: 2.3333333 | P8: 15.183016 | Q8: -7.0676323 | R8: -3.7144509 | S8: 2.773268 | T8: 59.783333 | U8: 2.773268 | V8: 59.783333 | W8: 255.24733 | X8: 98.620522 | Y8: 554.2233 | Z8: 1.8059774 | AA8: 2.928123 | AB8: 5.3465393 | AC8: 2.1470432 | AD8: 2.321042 | AE8: 2.2857106 | AF8: 3.0254973 | AG8: -0.13866734 | AH8: 4.0370748 | AI8: 2.1933515 | AJ8: 3.4549164 | AK8: 2.2623598 | AL8: 4.8098137 | AM8: 3.7859807 | AN8: -9.8336656 | AO8: -13.48988 | AP8: 31.691966 | AQ8: -14.733064 | AR8: 4.8098137 | AS8: 3.7859807 | AT8: 3.8354981 | AU8: -4.9476374 | AV8: -6.9055426 | AW8: -11.683903 | AX8: 34.620089 | AY8: -12.927087 | AZ8: 0.58215843 | BA8: 93.176343 | BB8: -0.0690083
A9: 2019Q3 | B9: 1069.6292 | C9: 1069.2171 | D9: 0.4120121 | E9: 435.28769 | F9: 438.46055 | G9: 2.3533333 | H9: 3.6606153 | I9: 2.28 | J9: 454.9188 | K9: 3.1180925 | L9: 97.752476 | M9: 404.25346 | N9: 2.19 | O9: 1.7966667 | P9: 15.960156 | Q9: -5.5982216 | R9: -0.94988411 | S9: 2.6298512 | T9: 56.37 | U9: 2.6298512 | V9: 56.37 | W9: 256.08933 | X9: 98.945847 | Y9: 554.55263 | Z9: 1.7342739 | AA9: 1.3173329 | AB9: -1.476765 | AC9: 2.4316002 | AD9: 1.5156159 | AE9: 2.0961186 | AF9: -2.9923808 | AG9: 0.33548167 | AH9: 2.340224 | AI9: 2.1831074 | AJ9: 1.2848407 | AK9: 2.2576991 | AL9: 5.8776426 | AM9: 2.7162685 | AN9: -22.556989 | AO9: -6.8592481 | AP9: -24.833258 | AQ9: -23.041863 | AR9: 5.8776426 | AS9: 2.7162685 | AT9: 11.058267 | AU9: 3.8746008 | AV9: -21.239656 | AW9: -5.1249742 | AX9: -23.515925 | AY9: -21.307589 | AZ9: 1.0553834 | BA9: 94.555595 | BB9: -0.07459173
A10: 2019Q4 | B10: 1065.4407 | C10: 1069.3972 | D10: -3.9564692 | E10: 436.25562 | F10: 438.88713 | G10: 1.8133333 | H10: 3.6256469 | I10: 2.1333333 | J10: 460.84423 | K10: 3.0296188 | L10: 98.602591 | M10: 404.58892 | N10: 1.6433333 | O10: 1.7933333 | P10: 13.985781 | Q10: 0.32720761 | R10: 5.9359823 | S10: 2.670932 | T10: 56.956667 | U10: 2.670932 | V10: 56.956667 | W10: 257.888 | X10: 99.640803 | Y10: 555.25254 | Z10: 2.0278839 | AA10: 2.7996161 | AB10: -16.753737 | AC10: -3.0253585 | AD10: 0.72018794 | AE10: 1.7076992 | AF10: -17.473925 | AG10: -4.7330577 | AH10: 3.87171 | AI10: 2.710635 | AJ10: 1.7062889 | AK10: 2.3664092 | AL10: 23.701717 | AM10: 7.8597468 | AN10: 3.4004629 | AO10: -6.6631278 | AP10: 1.341841 | AQ10: -5.6824129 | AR10: 23.701717 | AS10: 7.8597468 | AT10: 27.543465 | AU10: 11.852462 | AV10: 6.2000789 | AW10: -4.6352439 | AX10: 4.1414571 | AY10: -3.6545291 | AZ10: 2.1654211 | BA10: 100.32774 | BB10: 0.34422584
A11: 2020Q1 | B11: 1067.6913 | C11: 1069.8095 | D11: -2.1181977 | E11: 437.32338 | F11: 439.712 | G11: 1.6266667 | H11: 3.5972222 | I11: 2.55 | J11: 465.83997 | K11: -2.5458472 | L11: 93.900282 | M11: 382.33375 | N11: 1.26 | O11: 1.3766667 | P11: 31.224516 | Q11: 5.3229492 | R11: 6.0237975 | S11: 2.5574299 | T11: 45.756667 | U11: 2.5574299 | V11: 45.756667 | W11: 258.81767 | X11: 100 | Y11: 555.61238 | Z11: 2.1211122 | AA11: 1.4393768 | AB11: 9.0024182 | AC11: -0.97038618 | AD11: 1.6493323 | AE11: 1.5515445 | AF11: 7.3530859 | AG11: -2.5219307 | AH11: 4.2710277 | AI11: 3.6300091 | AJ11: 3.2994737 | AK11: 2.4363799 | AL11: 19.982966 | AM11: 13.593035 | AN11: -18.809239 | AO11: -11.949858 | AP11: -89.020674 | AQ11: -20.205032 | AR11: 19.982966 | AS11: 13.593035 | AT11: 0.35126076 | AU11: 10.697123 | AV11: -17.369862 | AW11: -9.8287454 | AX11: -87.581298 | AY11: -18.083919 | AZ11: 0.97155408 | BA11: 105.46717 | BB11: 1.1936292
A12: 2020Q2 | B12: 1052.7802 | C12: 1068.8652 | D12: -16.085072 | E12: 437.59422 | F12: 440.71086 | G12: 0.5 | H12: 3.5777778 | I12: 2.74 | J12: 464.07295 | K12: -5.4659898 | L12: 89.476433 | M12: 333.50822 | N12: 0.06 | O12: 0.68666667 | P12: 34.493651 | Q12: 3.5559272 | R12: -2.2579834 | S12: 2.4228825 | T12: 27.806667 | U12: 2.4228825 | V12: 27.806666 | W12: 256.292 | X12: 99.024152 | Y12: 554.63174 | Z12: 0.40844097 | AA12: -3.9225619 | AB12: -59.644718 | AC12: -17.2182 | AD12: -3.7772214 | AE12: 0.026978677 | AF12: -55.867496 | AG12: -17.245179 | AH12: 1.0833504 | AI12: 2.891578 | AJ12: 3.995451 | AK12: 2.5715135 | AL12: -7.0680881 | AM12: 10.62356 | AN12: -17.695393 | AO12: -13.915289 | AP12: -195.30212 | AQ12: -76.953553 | AR12: -7.0680881 | AS12: 10.62356 | AT12: -33.127124 | AU12: 1.4564675 | AV12: -21.617955 | AW12: -13.506848 | AX12: -199.22468 | AY12: -76.545112 | AZ12: -2.9121006 | BA12: 103.61991 | BB12: 0.32006449
A13: 2020Q3 | B13: 1057.9602 | C13: 1068.8933 | D13: -10.933025 | E13: 437.9296 | F13: 441.09898 | G13: 0.5 | H13: 3.5583333 | I13: 2.6 | J13: 461.80499 | K13: -0.1886628 | L13: 108.29153 | M13: 370.94073 | N13: 0.093333333 | O13: 0.65 | P13: 25.808906 | Q13: 1.2879696 | R13: 1.8199105 | S13: 2.9578865 | T13: 40.893333 | U13: 2.9578865 | V13: 40.893333 | W13: 259.22167 | X13: 100.15609 | Y13: 555.76836 | Z13: 1.215721 | AA13: 4.5464528 | AB13: 20.720359 | AC13: -11.668919 | AD13: 0.11217124 | AE13: -0.32388248 | AF13: 20.608187 | AG13: -11.345037 | AH13: 1.3415174 | AI13: 2.6419014 | AJ13: 1.5524912 | AK13: 2.6384262 | AL13: -9.0718307 | AM13: 6.8861912 | AN13: 75.260378 | AO13: 10.539052 | AP13: 149.73005 | AQ13: -33.312726 | AR13: -9.0718307 | AS13: 6.8861912 | AT13: 16.311576 | AU13: 2.7697946 | AV13: 79.806831 | AW13: 11.754773 | AX13: 154.2765 | AY13: -32.097005 | AZ13: -0.21097376 | BA13: 101.2963 | BB13: 0.0034752
A14: 2020Q4 | B14: 1065.4841 | C14: 1069.1966 | D14: -3.7125364 | E14: 439.10056 | F14: 441.97542 | G14: 0.5 | H14: 3.5388889 | I14: 2.51 | J14: 461.54818 | K14: 1.2660194 | L14: 117.11435 | M14: 373.96577 | N14: 0.09 | O14: 0.86333333 | P14: 25.621719 | Q14: 1.0311652 | R14: 6.9650386 | S14: 3.2540204 | T14: 42.453333 | U14: 3.2540204 | V14: 42.453333 | W14: 261.09167 | X14: 100.87861 | Y14: 556.48716 | Z14: 1.2346177 | AA14: 2.875203 | AB14: 30.095221 | AC14: 0.043320159 | AD14: 1.2132674 | AE14: -0.20061262 | AF14: 28.881954 | AG14: 0.24393278 | AH14: 4.6838458 | AI14: 2.8449353 | AJ14: 3.5057403 | AK14: 3.088289 | AL14: -1.0272175 | AM14: 0.70395757 | AN14: 35.291303 | AO14: 18.511762 | AP14: 12.10015 | AQ14: -30.623149 | AR14: -1.0272175 | AS14: 0.70395757 | AT14: 20.580513 | AU14: 1.0290564 | AV14: 38.166506 | AW14: 19.74638 | AX14: 14.975353 | AY14: -29.388531 | AZ14: 1.1781054 | BA14: 101.0365 | BB14: -0.2433537
... A42: 2027Q4 | B42: 1088.2872 | C42: 1088.6794 | D42: -0.39215237 | E42: 476.39901 | F42: 475.05314 | G42: 4.2405463 | H42: 4 | I42: 4.109857 | J42: 462 | K42: 2.9 | L42: 135.00293 | M42: 417.07604 | N42: 3.4 | O42: 4.2 | P42: 17 | Q42: -0.49728133 | R42: -6.9050119 | S42: 5.0378 | T42: 72.4 | U42: 5.0628022 | V42: 85 | W42: 339.68363 | X42: 131.24438 | Y42: 582.80147 | Z42: 1.9802627 | AA42: 1.9802627 | AB42: 1.6612232 | AC42: 1.9520081 | AD42: 1.4139953 | AE42: 1.8026018 | AF42: 0.208 | AG42: 0.125 | AH42: 3.3549293 | AI42: 2.716681 | AJ42: 1.3025148 | AK42: 2.9617154 | AL42: 0 | AM42: -1.1690396 | AN42: -3.9524463 | AO42: -9.6115763 | AP42: -6.9219865 | AQ42: -18.728161 | AR42: 0 | AS42: -1.1690396 | AT42: 5.679843 | AU42: -6.9183126 | AV42: -1.9721836 | AW42: -7.6313135 | AX42: -4.9417238 | AY42: -16.747898 | AZ42: 2.0524145 | BA42: 101.49403 | BB42: -0.2450344
A43: 2028Q1 | B43: 1088.7048 | C43: 1089.0768 | D43: -0.37200515 | E43: 477.03232 | F43: 475.98878 | G43: 4.2107615 | H43: 4 | I43: 4.1184334 | J43: 462.19891 | K43: 2.931586 | L43: 134.29609 | M43: 409.26967 | N43: 3.404 | O43: 4.18 | P43: 17 | Q43: -0.2983688 | R43: -3.8863997 | S43: NaN | T43: NaN | U43: NaN | V43: NaN | W43: NaN | X43: NaN | Y43: NaN | Z43: NaN | AA43: NaN | AB43: 1.6703856 | AC43: 2.1275425 | AD43: 1.5897967 | AE43: NaN | AF43: NaN | AG43: NaN | AH43: 2.533255 | AI43: 2.9505665 | AJ43: 3.7425766 | AK43: 2.8427531 | AL43: NaN | AM43: NaN | AN43: NaN | AO43: NaN | AP43: NaN | AQ43: NaN | AR43: NaN | AS43: NaN | AT43: NaN | AU43: NaN | AV43: NaN | AW43: NaN | AX43: NaN | AY43: NaN | AZ43: -1.2093216 | BA43: 101.69612 | BB43: 0.10781346
A44: 2028Q2 | B44: 1089.1223 | C44: 1089.505 | D44: -0.3827297 | E44: 477.82306 | F44: 477.12414 | G44: 4.1776597 | H44: 4 | I44: 4.1153321 | J44: 462.31826 | K44: 2.9531952 | L44: 133.76596 | M44: 403.81857 | N44: 3.40784 | O44: 4.162 | P44: 17 | Q44: -0.17902128 | R44: -1.7785331 | S44: NaN | T44: NaN | U44: NaN | V44: NaN | W44: NaN | X44: NaN | Y44: NaN | Z44: NaN | AA44: NaN | AB44: 1.6699595 | AC44: 1.6969894 | AD44: 1.7128577 | AE44: NaN | AF44: NaN | AG44: NaN | AH44: 3.162949 | AI44: 2.8691168 | AJ44: 4.5414284 | AK44: 2.9360671 | AL44: NaN | AM44: NaN | AN44: NaN | AO44: NaN | AP44: NaN | AQ44: NaN | AR44: NaN | AS44: NaN | AT44: NaN | AU44: NaN | AV44: NaN | AW44: NaN | AX44: NaN | AY44: NaN | AZ44: -1.3784794 | BA44: 101.81756 | BB44: -0.066950229
A45: 2028Q3 | B45: 1089.5937 | C45: 1089.9548 | D45: -0.36108234 | E45: 478.62705 | F45: 477.87716 | G45: 4.1812492 | H45: 4 | I45: 4.1088798 | J45: 462.38987 | K45: 2.967979 | L45: 133.36837 | M45: 400.01211 | N45: 3.4115264 | O45: 4.1458 | P45: 17 | Q45: -0.10741277 | R45: -0.30663085 | S45: NaN | T45: NaN | U45: NaN | V45: NaN | W45: NaN | X45: NaN | Y45: NaN | Z45: NaN | AA45: NaN | AB45: 1.8855898 | AC45: 1.7217895 | AD45: 1.7990004 | AE45: NaN | AF45: NaN | AG45: NaN | AH45: 3.2159843 | AI45: 3.0667794 | AJ45: 3.0120811 | AK45: 3.1496502 | AL45: NaN | AM45: NaN | AN45: NaN | AO45: NaN | AP45: NaN | AQ45: NaN | AR45: NaN | AS45: NaN | AT45: NaN | AU45: NaN | AV45: NaN | AW45: NaN | AX45: NaN | AY45: NaN | AZ45: 0.20390323 | BA45: 101.8905 | BB45: -0.082870827
A46: 2028Q4 | B46: 1090.0913 | C46: 1090.4196 | D46: -0.32831234 | E46: 479.25513 | F46: 478.32688 | G46: 4.1922667 | H46: 4 | I46: 4.0996825 | J46: 462.43283 | K46: 2.9780931 | L46: 133.07017 | M46: 397.3541 | N46: 3.4150653 | O46: 4.13122 | P46: 17 | Q46: -0.06444766 | R46: 0.72118374 | S46: NaN | T46: NaN | U46: NaN | V46: NaN | W46: NaN | X46: NaN | Y46: NaN | Z46: NaN | AA46: NaN | AB46: 1.9903803 | AC46: 1.8040788 | AD46: 1.8593003 | AE46: NaN | AF46: NaN | AG46: NaN | AH46: 2.5122937 | AI46: 2.8561205 | AJ46: 1.7988742 | AK46: 3.2737401 | AL46: NaN | AM46: NaN | AN46: NaN | AO46: NaN | AP46: NaN | AQ46: NaN | AR46: NaN | AS46: NaN | AT46: NaN | AU46: NaN | AV46: NaN | AW46: NaN | AX46: NaN | AY46: NaN | AZ46: 0.71341948 | BA46: 101.93429 | BB46: -0.41761957
A47: 2029Q1 | B47: 1090.6 | C47: 1090.895 | D47: -0.29493444 | E47: 480.0447 | F47: 479.36944 | G47: 4.1785487 | H47: 4 | I47: 4.0864014 | J47: 462.45861 | K47: 2.9850126 | L47: 132.84653 | M47: 395.49804 | N47: 3.4184627 | O47: 4.118098 | P47: 17 | Q47: -0.038668596 | R47: 1.4388964 | S47: NaN | T47: NaN | U47: NaN | V47: NaN | W47: NaN | X47: NaN | Y47: NaN | Z47: NaN | AA47: NaN | AB47: 2.0350218 | AC47: 1.8952379 | AD47: 1.9015102 | AE47: NaN | AF47: NaN | AG47: NaN | AH47: 3.1583088 | AI47: 3.0123839 | AJ47: 4.1702271 | AK47: 3.3806527 | AL47: NaN | AM47: NaN | AN47: NaN | AO47: NaN | AP47: NaN | AQ47: NaN | AR47: NaN | AS47: NaN | AT47: NaN | AU47: NaN | AV47: NaN | AW47: NaN | AX47: NaN | AY47: NaN | AZ47: -1.0119183 | BA47: 101.96057 | BB47: -0.36826874
A48: 2029Q2 | B48: 1091.114 | C48: 1091.3777 | D48: -0.26377348 | E48: 481.06571 | F48: 480.55872 | G48: 4.1826657 | H48: 4 | I48: 4.0696568 | J48: 462.47408 | K48: 2.9897466 | L48: 132.67879 | M48: 394.20198 | N48: 3.4217242 | O48: 4.1062882 | P48: 17 | Q48: -0.023201158 | R48: 1.940068 | S48: NaN | T48: NaN | U48: NaN | V48: NaN | W48: NaN | X48: NaN | Y48: NaN | Z48: NaN | AA48: NaN | AB48: 2.0557009 | AC48: 1.9916732 | AD48: 1.9310571 | AE48: NaN | AF48: NaN | AG48: NaN | AH48: 4.0840331 | AI48: 3.242655 | AJ48: 4.7571405 | AK48: 3.4345807 | AL48: NaN | AM48: NaN | AN48: NaN | AO48: NaN | AP48: NaN | AQ48: NaN | AR48: NaN | AS48: NaN | AT48: NaN | AU48: NaN | AV48: NaN | AW48: NaN | AX48: NaN | AY48: NaN | AZ48: -0.67310743 | BA48: 101.97634 | BB48: -0.19192575
A49: 2029Q3 | B49: 1091.6263 | C49: 1091.8657 | D49: -0.23937057 | E49: 481.98516 | F49: 481.32077 | G49: 4.207735 | H49: 4 | I49: 4.0497376 | J49: 462.48336 | K49: 2.9929852 | L49: 132.55299 | M49: 393.29694 | N49: 3.4248552 | O49: 4.0956594 | P49: 17 | Q49: -0.013920695 | R49: 2.2900311 | S49: NaN | T49: NaN | U49: NaN | V49: NaN | W49: NaN | X49: NaN | Y49: NaN | Z49: NaN | AA49: NaN | AB49: 2.0493516 | AC49: 2.0326137 | AD49: 1.95174 | AE49: NaN | AF49: NaN | AG49: NaN | AH49: 3.677797 | AI49: 3.3581081 | AJ49: 3.0481915 | AK49: 3.4436083 | AL49: NaN | AM49: NaN | AN49: NaN | AO49: NaN | AP49: NaN | AQ49: NaN | AR49: NaN | AS49: NaN | AT49: NaN | AU49: NaN | AV49: NaN | AW49: NaN | AX49: NaN | AY49: NaN | AZ49: 0.62960548 | BA49: 101.9858 | BB49: -0.08550019
A50: 2029Q4 | B50: 1092.134 | C50: 1092.3572 | D50: -0.22325624 | E50: 482.69808 | F50: 481.72921 | G50: 4.2070718 | H50: 4 | I50: 4.0305913 | J50: 462.48893 | K50: 2.9952009 | L50: 132.45864 | M50: 392.66497 | N50: 3.427861 | O50: 4.0860934 | P50: 17 | Q50: -0.0083524167 | R50: 2.5344068 | S50: NaN | T50: NaN | U50: NaN | V50: NaN | W50: NaN | X50: NaN | Y50: NaN | Z50: NaN | AA50: NaN | AB50: 2.0306753 | AC50: 2.0426874 | AD50: 1.966218 | AE50: NaN | AF50: NaN | AG50: NaN | AH50: 2.8516806 | AI50: 3.4429549 | AJ50: 1.6337651 | AK50: 3.402331 | AL50: NaN | AM50: NaN | AN50: NaN | AO50: NaN | AP50: NaN | AQ50: NaN | AR50: NaN | AS50: NaN | AT50: NaN | AU50: NaN | AV50: NaN | AW50: NaN | AX50: NaN | AY50: NaN | AZ50: 1.2179155 | BA50: 101.99148 | BB50: 0.040623822
